{
 "cells": [
  {
   "cell_type": "code",
   "execution_count": null,
   "metadata": {},
   "outputs": [],
   "source": [
    "import sys\n",
    "sys.path.append('../')\n",
    "from jurbey.jurbey import JURBEY\n",
    "import pandas as pd\n",
    "\n",
    "\n",
    "with open('1558537930325.jurbey', 'rb') as tempf:\n",
    "    g = JURBEY.load(tempf.read())\n",
    "    \n",
    "def populate_graph_with_max_speed(g):\n",
    "    for e in g.edges(data=True):\n",
    "        try:\n",
    "            g[e[0]][e[1]][\"speed\"] = float(g[e[0]][e[1]][\"data\"].metadata.get(\"maxspeed\", 10))\n",
    "        except ValueError:\n",
    "            g[e[0]][e[1]][\"speed\"] = 10\n",
    "    return g\n",
    "\n",
    "g = populate_graph_with_max_speed(g)\n"
   ]
  },
  {
   "cell_type": "code",
   "execution_count": 2,
   "metadata": {},
   "outputs": [
    {
     "name": "stdout",
     "output_type": "stream",
     "text": [
      "       source      target  direction  \\\n",
      "0      433577  2663205463          0   \n",
      "1  2663205463  1478322970          0   \n",
      "2  1478322970  2040106229          0   \n",
      "3      433660  1477659638          0   \n",
      "4  1477659638  1477659644          0   \n",
      "5  1477659644  1477659664          0   \n",
      "6  1477659664      243721          0   \n",
      "7      243721  2040378618          0   \n",
      "8  2040378618  1477659711          0   \n",
      "9  1477659711   429974831          0   \n",
      "\n",
      "                                                data          way  \\\n",
      "0  Arc(arcType=<ArcType.LANE_STRAIGHT: 'LANE_STRA...    [3996690]   \n",
      "1  Arc(arcType=<ArcType.LANE_STRAIGHT: 'LANE_STRA...    [3996690]   \n",
      "2  Arc(arcType=<ArcType.LANE_STRAIGHT: 'LANE_STRA...  [309175327]   \n",
      "3  Arc(arcType=<ArcType.LANE_STRAIGHT: 'LANE_STRA...    [3996691]   \n",
      "4  Arc(arcType=<ArcType.LANE_STRAIGHT: 'LANE_STRA...    [3996691]   \n",
      "5  Arc(arcType=<ArcType.LANE_STRAIGHT: 'LANE_STRA...    [3996691]   \n",
      "6  Arc(arcType=<ArcType.LANE_STRAIGHT: 'LANE_STRA...    [3996691]   \n",
      "7  Arc(arcType=<ArcType.LANE_STRAIGHT: 'LANE_STRA...    [3996691]   \n",
      "8  Arc(arcType=<ArcType.LANE_STRAIGHT: 'LANE_STRA...    [3996691]   \n",
      "9  Arc(arcType=<ArcType.LANE_STRAIGHT: 'LANE_STRA...    [3996691]   \n",
      "\n",
      "  vehicleAccessibility  rate  speed  \n",
      "0    [VehicleType.All]     1  100.0  \n",
      "1    [VehicleType.All]     1  100.0  \n",
      "2    [VehicleType.All]     1  100.0  \n",
      "3    [VehicleType.All]     1  100.0  \n",
      "4    [VehicleType.All]     1  100.0  \n",
      "5    [VehicleType.All]     1  100.0  \n",
      "6    [VehicleType.All]     1  100.0  \n",
      "7    [VehicleType.All]     1  100.0  \n",
      "8    [VehicleType.All]     1  100.0  \n",
      "9    [VehicleType.All]     1  100.0  \n"
     ]
    }
   ],
   "source": [
    "import networkx as nx\n",
    "df = nx.to_pandas_edgelist(g)\n",
    "print(df[0:10])"
   ]
  },
  {
   "cell_type": "code",
   "execution_count": 3,
   "metadata": {},
   "outputs": [],
   "source": [
    "df = df[['source', 'target', 'speed']]\n",
    "df.rename(columns={'speed': 'weight'})\n",
    "df = df[0:100]"
   ]
  },
  {
   "cell_type": "code",
   "execution_count": 5,
   "metadata": {},
   "outputs": [
    {
     "ename": "Exception",
     "evalue": "KeyError:Traceback (most recent call last):\n  File \"/Users/nguytu3/anaconda3/lib/python3.7/site-packages/pandas/core/indexes/base.py\", line 2657, in get_loc\n    return self._engine.get_loc(key)\n  File \"pandas/_libs/index.pyx\", line 108, in pandas._libs.index.IndexEngine.get_loc\n  File \"pandas/_libs/index.pyx\", line 132, in pandas._libs.index.IndexEngine.get_loc\n  File \"pandas/_libs/hashtable_class_helper.pxi\", line 1601, in pandas._libs.hashtable.PyObjectHashTable.get_item\n  File \"pandas/_libs/hashtable_class_helper.pxi\", line 1608, in pandas._libs.hashtable.PyObjectHashTable.get_item\nKeyError: 0\n\nDuring handling of the above exception, another exception occurred:\n\nTraceback (most recent call last):\n  File \"/Users/nguytu3/anaconda3/lib/python3.7/site-packages/torch/utils/data/_utils/worker.py\", line 99, in _worker_loop\n    samples = collate_fn([dataset[i] for i in batch_indices])\n  File \"/Users/nguytu3/anaconda3/lib/python3.7/site-packages/torch/utils/data/_utils/worker.py\", line 99, in <listcomp>\n    samples = collate_fn([dataset[i] for i in batch_indices])\n  File \"/Users/nguytu3/anaconda3/lib/python3.7/site-packages/pandas/core/frame.py\", line 2927, in __getitem__\n    indexer = self.columns.get_loc(key)\n  File \"/Users/nguytu3/anaconda3/lib/python3.7/site-packages/pandas/core/indexes/base.py\", line 2659, in get_loc\n    return self._engine.get_loc(self._maybe_cast_indexer(key))\n  File \"pandas/_libs/index.pyx\", line 108, in pandas._libs.index.IndexEngine.get_loc\n  File \"pandas/_libs/index.pyx\", line 132, in pandas._libs.index.IndexEngine.get_loc\n  File \"pandas/_libs/hashtable_class_helper.pxi\", line 1601, in pandas._libs.hashtable.PyObjectHashTable.get_item\n  File \"pandas/_libs/hashtable_class_helper.pxi\", line 1608, in pandas._libs.hashtable.PyObjectHashTable.get_item\nKeyError: 0\n",
     "output_type": "error",
     "traceback": [
      "\u001b[0;31m---------------------------------------------------------------------------\u001b[0m",
      "\u001b[0;31mException\u001b[0m                                 Traceback (most recent call last)",
      "\u001b[0;32m<ipython-input-5-3228e821a03e>\u001b[0m in \u001b[0;36m<module>\u001b[0;34m\u001b[0m\n\u001b[1;32m      2\u001b[0m \u001b[0;32mfrom\u001b[0m \u001b[0mfastai\u001b[0m\u001b[0;34m.\u001b[0m\u001b[0mtabular\u001b[0m \u001b[0;32mimport\u001b[0m \u001b[0mdata\u001b[0m\u001b[0;34m,\u001b[0m \u001b[0moptim\u001b[0m\u001b[0;34m\u001b[0m\u001b[0;34m\u001b[0m\u001b[0m\n\u001b[1;32m      3\u001b[0m \u001b[0;34m\u001b[0m\u001b[0m\n\u001b[0;32m----> 4\u001b[0;31m \u001b[0mtrain_nmf\u001b[0m\u001b[0;34m(\u001b[0m\u001b[0mdataset\u001b[0m\u001b[0;34m=\u001b[0m\u001b[0mdf\u001b[0m\u001b[0;34m)\u001b[0m\u001b[0;34m\u001b[0m\u001b[0;34m\u001b[0m\u001b[0m\n\u001b[0m",
      "\u001b[0;32m~/Work/speed-imputation/src/nmf/fast_nmf.py\u001b[0m in \u001b[0;36mtrain_nmf\u001b[0;34m(dataset, num_factors, n_epochs, lr, weight_decay, momentum)\u001b[0m\n\u001b[1;32m     39\u001b[0m     \u001b[0;32mfor\u001b[0m \u001b[0mepoch\u001b[0m \u001b[0;32min\u001b[0m \u001b[0mrange\u001b[0m\u001b[0;34m(\u001b[0m\u001b[0mn_epochs\u001b[0m\u001b[0;34m)\u001b[0m\u001b[0;34m:\u001b[0m\u001b[0;34m\u001b[0m\u001b[0;34m\u001b[0m\u001b[0m\n\u001b[1;32m     40\u001b[0m         \u001b[0mrunning_loss\u001b[0m \u001b[0;34m=\u001b[0m \u001b[0;36m0.0\u001b[0m\u001b[0;34m\u001b[0m\u001b[0;34m\u001b[0m\u001b[0m\n\u001b[0;32m---> 41\u001b[0;31m         \u001b[0;32mfor\u001b[0m \u001b[0mi\u001b[0m\u001b[0;34m,\u001b[0m \u001b[0mbatch_data\u001b[0m \u001b[0;32min\u001b[0m \u001b[0menumerate\u001b[0m\u001b[0;34m(\u001b[0m\u001b[0mtrain_loader\u001b[0m\u001b[0;34m)\u001b[0m\u001b[0;34m:\u001b[0m\u001b[0;34m\u001b[0m\u001b[0;34m\u001b[0m\u001b[0m\n\u001b[0m\u001b[1;32m     42\u001b[0m             \u001b[0minputs\u001b[0m \u001b[0;34m=\u001b[0m \u001b[0mbatch_data\u001b[0m\u001b[0;34m.\u001b[0m\u001b[0mlong\u001b[0m\u001b[0;34m(\u001b[0m\u001b[0;34m)\u001b[0m\u001b[0;34m.\u001b[0m\u001b[0mcuda\u001b[0m\u001b[0;34m(\u001b[0m\u001b[0;34m)\u001b[0m\u001b[0;34m\u001b[0m\u001b[0;34m\u001b[0m\u001b[0m\n\u001b[1;32m     43\u001b[0m             \u001b[0mactual_out\u001b[0m \u001b[0;34m=\u001b[0m \u001b[0mV\u001b[0m\u001b[0;34m(\u001b[0m\u001b[0mbatch_data\u001b[0m\u001b[0;34m[\u001b[0m\u001b[0;34m:\u001b[0m\u001b[0;34m,\u001b[0m \u001b[0;36m2\u001b[0m\u001b[0;34m]\u001b[0m\u001b[0;34m.\u001b[0m\u001b[0mfloat\u001b[0m\u001b[0;34m(\u001b[0m\u001b[0;34m)\u001b[0m\u001b[0;34m)\u001b[0m\u001b[0;34m.\u001b[0m\u001b[0mcuda\u001b[0m\u001b[0;34m(\u001b[0m\u001b[0;34m)\u001b[0m\u001b[0;34m\u001b[0m\u001b[0;34m\u001b[0m\u001b[0m\n",
      "\u001b[0;32m~/anaconda3/lib/python3.7/site-packages/torch/utils/data/dataloader.py\u001b[0m in \u001b[0;36m__next__\u001b[0;34m(self)\u001b[0m\n\u001b[1;32m    580\u001b[0m                 \u001b[0mself\u001b[0m\u001b[0;34m.\u001b[0m\u001b[0mreorder_dict\u001b[0m\u001b[0;34m[\u001b[0m\u001b[0midx\u001b[0m\u001b[0;34m]\u001b[0m \u001b[0;34m=\u001b[0m \u001b[0mbatch\u001b[0m\u001b[0;34m\u001b[0m\u001b[0;34m\u001b[0m\u001b[0m\n\u001b[1;32m    581\u001b[0m                 \u001b[0;32mcontinue\u001b[0m\u001b[0;34m\u001b[0m\u001b[0;34m\u001b[0m\u001b[0m\n\u001b[0;32m--> 582\u001b[0;31m             \u001b[0;32mreturn\u001b[0m \u001b[0mself\u001b[0m\u001b[0;34m.\u001b[0m\u001b[0m_process_next_batch\u001b[0m\u001b[0;34m(\u001b[0m\u001b[0mbatch\u001b[0m\u001b[0;34m)\u001b[0m\u001b[0;34m\u001b[0m\u001b[0;34m\u001b[0m\u001b[0m\n\u001b[0m\u001b[1;32m    583\u001b[0m \u001b[0;34m\u001b[0m\u001b[0m\n\u001b[1;32m    584\u001b[0m     \u001b[0mnext\u001b[0m \u001b[0;34m=\u001b[0m \u001b[0m__next__\u001b[0m  \u001b[0;31m# Python 2 compatibility\u001b[0m\u001b[0;34m\u001b[0m\u001b[0;34m\u001b[0m\u001b[0m\n",
      "\u001b[0;32m~/anaconda3/lib/python3.7/site-packages/torch/utils/data/dataloader.py\u001b[0m in \u001b[0;36m_process_next_batch\u001b[0;34m(self, batch)\u001b[0m\n\u001b[1;32m    604\u001b[0m             \u001b[0;31m# a python bug https://bugs.python.org/issue2651\u001b[0m\u001b[0;34m\u001b[0m\u001b[0;34m\u001b[0m\u001b[0;34m\u001b[0m\u001b[0m\n\u001b[1;32m    605\u001b[0m             \u001b[0;32mif\u001b[0m \u001b[0mbatch\u001b[0m\u001b[0;34m.\u001b[0m\u001b[0mexc_type\u001b[0m \u001b[0;34m==\u001b[0m \u001b[0mKeyError\u001b[0m \u001b[0;32mand\u001b[0m \u001b[0;34m\"\\n\"\u001b[0m \u001b[0;32min\u001b[0m \u001b[0mbatch\u001b[0m\u001b[0;34m.\u001b[0m\u001b[0mexc_msg\u001b[0m\u001b[0;34m:\u001b[0m\u001b[0;34m\u001b[0m\u001b[0;34m\u001b[0m\u001b[0m\n\u001b[0;32m--> 606\u001b[0;31m                 \u001b[0;32mraise\u001b[0m \u001b[0mException\u001b[0m\u001b[0;34m(\u001b[0m\u001b[0;34m\"KeyError:\"\u001b[0m \u001b[0;34m+\u001b[0m \u001b[0mbatch\u001b[0m\u001b[0;34m.\u001b[0m\u001b[0mexc_msg\u001b[0m\u001b[0;34m)\u001b[0m\u001b[0;34m\u001b[0m\u001b[0;34m\u001b[0m\u001b[0m\n\u001b[0m\u001b[1;32m    607\u001b[0m             \u001b[0;32melse\u001b[0m\u001b[0;34m:\u001b[0m\u001b[0;34m\u001b[0m\u001b[0;34m\u001b[0m\u001b[0m\n\u001b[1;32m    608\u001b[0m                 \u001b[0;32mraise\u001b[0m \u001b[0mbatch\u001b[0m\u001b[0;34m.\u001b[0m\u001b[0mexc_type\u001b[0m\u001b[0;34m(\u001b[0m\u001b[0mbatch\u001b[0m\u001b[0;34m.\u001b[0m\u001b[0mexc_msg\u001b[0m\u001b[0;34m)\u001b[0m\u001b[0;34m\u001b[0m\u001b[0;34m\u001b[0m\u001b[0m\n",
      "\u001b[0;31mException\u001b[0m: KeyError:Traceback (most recent call last):\n  File \"/Users/nguytu3/anaconda3/lib/python3.7/site-packages/pandas/core/indexes/base.py\", line 2657, in get_loc\n    return self._engine.get_loc(key)\n  File \"pandas/_libs/index.pyx\", line 108, in pandas._libs.index.IndexEngine.get_loc\n  File \"pandas/_libs/index.pyx\", line 132, in pandas._libs.index.IndexEngine.get_loc\n  File \"pandas/_libs/hashtable_class_helper.pxi\", line 1601, in pandas._libs.hashtable.PyObjectHashTable.get_item\n  File \"pandas/_libs/hashtable_class_helper.pxi\", line 1608, in pandas._libs.hashtable.PyObjectHashTable.get_item\nKeyError: 0\n\nDuring handling of the above exception, another exception occurred:\n\nTraceback (most recent call last):\n  File \"/Users/nguytu3/anaconda3/lib/python3.7/site-packages/torch/utils/data/_utils/worker.py\", line 99, in _worker_loop\n    samples = collate_fn([dataset[i] for i in batch_indices])\n  File \"/Users/nguytu3/anaconda3/lib/python3.7/site-packages/torch/utils/data/_utils/worker.py\", line 99, in <listcomp>\n    samples = collate_fn([dataset[i] for i in batch_indices])\n  File \"/Users/nguytu3/anaconda3/lib/python3.7/site-packages/pandas/core/frame.py\", line 2927, in __getitem__\n    indexer = self.columns.get_loc(key)\n  File \"/Users/nguytu3/anaconda3/lib/python3.7/site-packages/pandas/core/indexes/base.py\", line 2659, in get_loc\n    return self._engine.get_loc(self._maybe_cast_indexer(key))\n  File \"pandas/_libs/index.pyx\", line 108, in pandas._libs.index.IndexEngine.get_loc\n  File \"pandas/_libs/index.pyx\", line 132, in pandas._libs.index.IndexEngine.get_loc\n  File \"pandas/_libs/hashtable_class_helper.pxi\", line 1601, in pandas._libs.hashtable.PyObjectHashTable.get_item\n  File \"pandas/_libs/hashtable_class_helper.pxi\", line 1608, in pandas._libs.hashtable.PyObjectHashTable.get_item\nKeyError: 0\n"
     ]
    }
   ],
   "source": [
    "from src.nmf.fast_nmf import train_nmf\n",
    "from fastai.tabular import data, optim\n",
    "\n",
    "train_nmf(dataset=df)"
   ]
  },
  {
   "cell_type": "code",
   "execution_count": null,
   "metadata": {},
   "outputs": [],
   "source": []
  },
  {
   "cell_type": "code",
   "execution_count": null,
   "metadata": {},
   "outputs": [],
   "source": []
  }
 ],
 "metadata": {
  "kernelspec": {
   "display_name": "Python 3",
   "language": "python",
   "name": "python3"
  },
  "language_info": {
   "codemirror_mode": {
    "name": "ipython",
    "version": 3
   },
   "file_extension": ".py",
   "mimetype": "text/x-python",
   "name": "python",
   "nbconvert_exporter": "python",
   "pygments_lexer": "ipython3",
   "version": "3.7.1"
  }
 },
 "nbformat": 4,
 "nbformat_minor": 2
}
